F
======================================================================
FAIL: test_can_start_a_list_and_retriveve_it_later (__main__.NewVisitorTest)
----------------------------------------------------------------------
Traceback (most recent call last):
  File "functional_test.py", line 20, in test_can_start_a_list_and_retriveve_it_later
    self.assertIn('To-Do', self.browser.title)
AssertionError: 'To-Do' not found in 'TypeError at /'

----------------------------------------------------------------------
Ran 1 test in 3.638s

FAILED (failures=1)
