E
======================================================================
ERROR: test_can_start_a_list_and_retrieve_it_later (__main__.NewVisitorTest)
----------------------------------------------------------------------
Traceback (most recent call last):
  File "functional_tests.py", line 43, in test_can_start_a_list_and_retrieve_it_later
    self.check_for_row_in_list_table('1: Buy peacock feathers')
  File "functional_tests.py", line 17, in check_for_row_in_list_table
    self.assertIn(row_text, [row.text for row in rows])
  File "functional_tests.py", line 17, in <listcomp>
    self.assertIn(row_text, [row.text for row in rows])
  File "/usr/local/lib/python3.5/site-packages/selenium/webdriver/remote/webelement.py", line 73, in text
    return self._execute(Command.GET_ELEMENT_TEXT)['value']
  File "/usr/local/lib/python3.5/site-packages/selenium/webdriver/remote/webelement.py", line 494, in _execute
    return self._parent.execute(command, params)
  File "/usr/local/lib/python3.5/site-packages/selenium/webdriver/remote/webdriver.py", line 236, in execute
    self.error_handler.check_response(response)
  File "/usr/local/lib/python3.5/site-packages/selenium/webdriver/remote/errorhandler.py", line 192, in check_response
    raise exception_class(message, screen, stacktrace)
selenium.common.exceptions.StaleElementReferenceException: Message: The element reference is stale. Either the element is no longer attached to the DOM or the page has been refreshed.


----------------------------------------------------------------------
Ran 1 test in 3.644s

FAILED (errors=1)
