....F.E.
======================================================================
ERROR: test_redirects_after_POST (lists.tests.NewListTest)
----------------------------------------------------------------------
Traceback (most recent call last):
  File "/Users/hadesshark/note-and-code/code/python/TDD/superlists/lists/tests.py", line 106, in test_redirects_after_POST
    self.assertRedirects(response, '/lists/the-only-list-in-the-world/')
  File "/usr/local/lib/python3.5/site-packages/django/test/testcases.py", line 290, in assertRedirects
    secure=(scheme == 'https'))
  File "/usr/local/lib/python3.5/site-packages/django/test/client.py", line 500, in get
    **extra)
  File "/usr/local/lib/python3.5/site-packages/django/test/client.py", line 303, in get
    return self.generic('GET', path, secure=secure, **r)
  File "/usr/local/lib/python3.5/site-packages/django/test/client.py", line 379, in generic
    return self.request(**r)
  File "/usr/local/lib/python3.5/site-packages/django/test/client.py", line 466, in request
    six.reraise(*exc_info)
  File "/usr/local/lib/python3.5/site-packages/django/utils/six.py", line 659, in reraise
    raise value
  File "/usr/local/lib/python3.5/site-packages/django/core/handlers/base.py", line 132, in get_response
    response = wrapped_callback(request, *callback_args, **callback_kwargs)
  File "/Users/hadesshark/note-and-code/code/python/TDD/superlists/lists/views.py", line 10, in view_list
    list_ = List.objects.get(id=list_id)
  File "/usr/local/lib/python3.5/site-packages/django/db/models/manager.py", line 127, in manager_method
    return getattr(self.get_queryset(), name)(*args, **kwargs)
  File "/usr/local/lib/python3.5/site-packages/django/db/models/query.py", line 325, in get
    clone = self.filter(*args, **kwargs)
  File "/usr/local/lib/python3.5/site-packages/django/db/models/query.py", line 679, in filter
    return self._filter_or_exclude(False, *args, **kwargs)
  File "/usr/local/lib/python3.5/site-packages/django/db/models/query.py", line 697, in _filter_or_exclude
    clone.query.add_q(Q(*args, **kwargs))
  File "/usr/local/lib/python3.5/site-packages/django/db/models/sql/query.py", line 1309, in add_q
    clause, require_inner = self._add_q(where_part, self.used_aliases)
  File "/usr/local/lib/python3.5/site-packages/django/db/models/sql/query.py", line 1337, in _add_q
    allow_joins=allow_joins, split_subq=split_subq,
  File "/usr/local/lib/python3.5/site-packages/django/db/models/sql/query.py", line 1208, in build_filter
    condition = self.build_lookup(lookups, col, value)
  File "/usr/local/lib/python3.5/site-packages/django/db/models/sql/query.py", line 1101, in build_lookup
    return final_lookup(lhs, rhs)
  File "/usr/local/lib/python3.5/site-packages/django/db/models/lookups.py", line 101, in __init__
    self.rhs = self.get_prep_lookup()
  File "/usr/local/lib/python3.5/site-packages/django/db/models/lookups.py", line 139, in get_prep_lookup
    return self.lhs.output_field.get_prep_lookup(self.lookup_name, self.rhs)
  File "/usr/local/lib/python3.5/site-packages/django/db/models/fields/__init__.py", line 727, in get_prep_lookup
    return self.get_prep_value(value)
  File "/usr/local/lib/python3.5/site-packages/django/db/models/fields/__init__.py", line 985, in get_prep_value
    return int(value)
ValueError: invalid literal for int() with base 10: 'the-only-list-in-the-world'

======================================================================
FAIL: test_displays_only_items_for_that_list (lists.tests.ListViewTest)
----------------------------------------------------------------------
Traceback (most recent call last):
  File "/Users/hadesshark/note-and-code/code/python/TDD/superlists/lists/tests.py", line 87, in test_displays_only_items_for_that_list
    self.assertNotContains(response, 'other list item 1')
  File "/usr/local/lib/python3.5/site-packages/django/test/testcases.py", line 371, in assertNotContains
    msg_prefix + "Response should not contain %s" % text_repr)
AssertionError: 1 != 0 : Response should not contain 'other list item 1'

----------------------------------------------------------------------
Ran 8 tests in 0.059s

FAILED (failures=1, errors=1)
