F
======================================================================
FAIL: test_can_start_a_list_and_retrieve_it_later (__main__.NewVisitorTest)
----------------------------------------------------------------------
Traceback (most recent call last):
  File "functional_tests.py", line 43, in test_can_start_a_list_and_retrieve_it_later
    "New to-do item did not appear in talbe"
AssertionError: False is not true : New to-do item did not appear in talbe

----------------------------------------------------------------------
Ran 1 test in 6.786s

FAILED (failures=1)
