Traceback (most recent call last):
  File "functional_tests.py", line 4, in <module>
    browser.get('http://localhost:8000')
  File "/usr/local/lib/python3.5/site-packages/selenium/webdriver/remote/webdriver.py", line 248, in get
    self.execute(Command.GET, {'url': url})
  File "/usr/local/lib/python3.5/site-packages/selenium/webdriver/remote/webdriver.py", line 236, in execute
    self.error_handler.check_response(response)
  File "/usr/local/lib/python3.5/site-packages/selenium/webdriver/remote/errorhandler.py", line 192, in check_response
    raise exception_class(message, screen, stacktrace)
selenium.common.exceptions.WebDriverException: Message: Error loading page

